<?xml version="1.0" encoding="UTF-8"?>
<!-- Generated by org.testng.reporters.JUnitReportReporter -->
<testsuite skipped="6" hostname="BLRLAP653" name="RunFailedTestPractise.SampleTest" tests="10" failures="2" timestamp="11 May 2018 11:56:52 GMT" time="0.027" errors="0">
  <testcase name="test1" time="0.015" classname="RunFailedTestPractise.SampleTest"/>
  <testcase name="test3" time="0.001" classname="RunFailedTestPractise.SampleTest">
    <failure type="java.lang.AssertionError" message="expected [true] but found [false]">
      <![CDATA[java.lang.AssertionError: expected [true] but found [false]
	at org.testng.Assert.fail(Assert.java:93)
	at org.testng.Assert.failNotEquals(Assert.java:512)
	at org.testng.Assert.assertEqualsImpl(Assert.java:134)
	at org.testng.Assert.assertEquals(Assert.java:115)
	at org.testng.Assert.assertEquals(Assert.java:304)
	at org.testng.Assert.assertEquals(Assert.java:314)
	at RunFailedTestPractise.SampleTest.test3(SampleTest.java:25)
	at sun.reflect.NativeMethodAccessorImpl.invoke0(Native Method)
	at sun.reflect.NativeMethodAccessorImpl.invoke(NativeMethodAccessorImpl.java:62)
	at sun.reflect.DelegatingMethodAccessorImpl.invoke(DelegatingMethodAccessorImpl.java:43)
	at java.lang.reflect.Method.invoke(Method.java:498)
	at org.testng.internal.MethodInvocationHelper.invokeMethod(MethodInvocationHelper.java:108)
	at org.testng.internal.Invoker.invokeMethod(Invoker.java:669)
	at org.testng.internal.Invoker.retryFailed(Invoker.java:1022)
	at org.testng.internal.Invoker.invokeTestMethods(Invoker.java:1223)
	at org.testng.internal.TestMethodWorker.invokeTestMethods(TestMethodWorker.java:125)
	at org.testng.internal.TestMethodWorker.run(TestMethodWorker.java:109)
	at org.testng.TestRunner.privateRun(TestRunner.java:776)
	at org.testng.TestRunner.run(TestRunner.java:634)
	at org.testng.SuiteRunner.runTest(SuiteRunner.java:425)
	at org.testng.SuiteRunner.runSequentially(SuiteRunner.java:420)
	at org.testng.SuiteRunner.privateRun(SuiteRunner.java:385)
	at org.testng.SuiteRunner.run(SuiteRunner.java:334)
	at org.testng.SuiteRunnerWorker.runSuite(SuiteRunnerWorker.java:52)
	at org.testng.SuiteRunnerWorker.run(SuiteRunnerWorker.java:86)
	at org.testng.TestNG.runSuitesSequentially(TestNG.java:1318)
	at org.testng.TestNG.runSuitesLocally(TestNG.java:1243)
	at org.testng.TestNG.runSuites(TestNG.java:1161)
	at org.testng.TestNG.run(TestNG.java:1129)
	at Listners_RuntestDynamically.Runner1.main(Runner1.java:17)
]]>
    </failure>
  </testcase> <!-- test3 -->
  <testcase name="test3" time="0.001" classname="RunFailedTestPractise.SampleTest">
    <skipped/>
  </testcase> <!-- test3 -->
  <testcase name="test2" time="0.001" classname="RunFailedTestPractise.SampleTest">
    <skipped/>
  </testcase> <!-- test2 -->
  <testcase name="test2" time="0.006" classname="RunFailedTestPractise.SampleTest">
    <skipped/>
  </testcase> <!-- test2 -->
  <testcase name="test2" time="0.001" classname="RunFailedTestPractise.SampleTest">
    <skipped/>
  </testcase> <!-- test2 -->
  <testcase name="test3" time="0.001" classname="RunFailedTestPractise.SampleTest">
    <skipped/>
  </testcase> <!-- test3 -->
  <testcase name="test3" time="0.000" classname="RunFailedTestPractise.SampleTest">
    <skipped/>
  </testcase> <!-- test3 -->
  <testcase name="test4" time="0.000" classname="RunFailedTestPractise.SampleTest"/>
  <testcase name="test2" time="0.001" classname="RunFailedTestPractise.SampleTest">
    <failure type="java.lang.AssertionError" message="expected [true] but found [false]">
      <![CDATA[java.lang.AssertionError: expected [true] but found [false]
	at org.testng.Assert.fail(Assert.java:93)
	at org.testng.Assert.failNotEquals(Assert.java:512)
	at org.testng.Assert.assertEqualsImpl(Assert.java:134)
	at org.testng.Assert.assertEquals(Assert.java:115)
	at org.testng.Assert.assertEquals(Assert.java:304)
	at org.testng.Assert.assertEquals(Assert.java:314)
	at RunFailedTestPractise.SampleTest.test2(SampleTest.java:19)
	at sun.reflect.NativeMethodAccessorImpl.invoke0(Native Method)
	at sun.reflect.NativeMethodAccessorImpl.invoke(NativeMethodAccessorImpl.java:62)
	at sun.reflect.DelegatingMethodAccessorImpl.invoke(DelegatingMethodAccessorImpl.java:43)
	at java.lang.reflect.Method.invoke(Method.java:498)
	at org.testng.internal.MethodInvocationHelper.invokeMethod(MethodInvocationHelper.java:108)
	at org.testng.internal.Invoker.invokeMethod(Invoker.java:669)
	at org.testng.internal.Invoker.retryFailed(Invoker.java:1022)
	at org.testng.internal.Invoker.invokeTestMethods(Invoker.java:1223)
	at org.testng.internal.TestMethodWorker.invokeTestMethods(TestMethodWorker.java:125)
	at org.testng.internal.TestMethodWorker.run(TestMethodWorker.java:109)
	at org.testng.TestRunner.privateRun(TestRunner.java:776)
	at org.testng.TestRunner.run(TestRunner.java:634)
	at org.testng.SuiteRunner.runTest(SuiteRunner.java:425)
	at org.testng.SuiteRunner.runSequentially(SuiteRunner.java:420)
	at org.testng.SuiteRunner.privateRun(SuiteRunner.java:385)
	at org.testng.SuiteRunner.run(SuiteRunner.java:334)
	at org.testng.SuiteRunnerWorker.runSuite(SuiteRunnerWorker.java:52)
	at org.testng.SuiteRunnerWorker.run(SuiteRunnerWorker.java:86)
	at org.testng.TestNG.runSuitesSequentially(TestNG.java:1318)
	at org.testng.TestNG.runSuitesLocally(TestNG.java:1243)
	at org.testng.TestNG.runSuites(TestNG.java:1161)
	at org.testng.TestNG.run(TestNG.java:1129)
	at Listners_RuntestDynamically.Runner1.main(Runner1.java:17)
]]>
    </failure>
  </testcase> <!-- test2 -->
</testsuite> <!-- RunFailedTestPractise.SampleTest -->
