<?xml version="1.0" encoding="UTF-8"?>
<!-- Generated by org.testng.reporters.JUnitReportReporter -->
<testsuite skipped="6" hostname="BLRLAP653" name="runfailedtest1.SampleTest" tests="9" failures="2" timestamp="22 Jan 2019 14:10:59 GMT" time="0.066" errors="0">
  <testcase name="test1" time="0.004" classname="runfailedtest1.SampleTest">
    <skipped/>
  </testcase> <!-- test1 -->
  <testcase name="test2" time="0.003" classname="runfailedtest1.SampleTest"/>
  <testcase name="test1" time="0.005" classname="runfailedtest1.SampleTest">
    <skipped/>
  </testcase> <!-- test1 -->
  <testcase name="test3" time="0.004" classname="runfailedtest1.SampleTest">
    <skipped/>
  </testcase> <!-- test3 -->
  <testcase name="test3" time="0.003" classname="runfailedtest1.SampleTest">
    <skipped/>
  </testcase> <!-- test3 -->
  <testcase name="test3" time="0.006" classname="runfailedtest1.SampleTest">
    <skipped/>
  </testcase> <!-- test3 -->
  <testcase name="test1" time="0.004" classname="runfailedtest1.SampleTest">
    <failure type="java.lang.AssertionError" message="expected [Hi] but found [hi]">
      <![CDATA[java.lang.AssertionError: expected [Hi] but found [hi]
	at org.testng.Assert.fail(Assert.java:93)
	at org.testng.Assert.failNotEquals(Assert.java:512)
	at org.testng.Assert.assertEqualsImpl(Assert.java:134)
	at org.testng.Assert.assertEquals(Assert.java:115)
	at org.testng.Assert.assertEquals(Assert.java:189)
	at org.testng.Assert.assertEquals(Assert.java:199)
	at runfailedtest1.SampleTest.test1(SampleTest.java:14)
	at sun.reflect.NativeMethodAccessorImpl.invoke0(Native Method)
	at sun.reflect.NativeMethodAccessorImpl.invoke(NativeMethodAccessorImpl.java:62)
	at sun.reflect.DelegatingMethodAccessorImpl.invoke(DelegatingMethodAccessorImpl.java:43)
	at java.lang.reflect.Method.invoke(Method.java:498)
	at org.testng.internal.MethodInvocationHelper.invokeMethod(MethodInvocationHelper.java:108)
	at org.testng.internal.Invoker.invokeMethod(Invoker.java:669)
	at org.testng.internal.Invoker.retryFailed(Invoker.java:1022)
	at org.testng.internal.Invoker.invokeTestMethods(Invoker.java:1223)
	at org.testng.internal.TestMethodWorker.invokeTestMethods(TestMethodWorker.java:125)
	at org.testng.internal.TestMethodWorker.run(TestMethodWorker.java:109)
	at org.testng.TestRunner.privateRun(TestRunner.java:776)
	at org.testng.TestRunner.run(TestRunner.java:634)
	at org.testng.SuiteRunner.runTest(SuiteRunner.java:425)
	at org.testng.SuiteRunner.runSequentially(SuiteRunner.java:420)
	at org.testng.SuiteRunner.privateRun(SuiteRunner.java:385)
	at org.testng.SuiteRunner.run(SuiteRunner.java:334)
	at org.testng.SuiteRunnerWorker.runSuite(SuiteRunnerWorker.java:52)
	at org.testng.SuiteRunnerWorker.run(SuiteRunnerWorker.java:86)
	at org.testng.TestNG.runSuitesSequentially(TestNG.java:1318)
	at org.testng.TestNG.runSuitesLocally(TestNG.java:1243)
	at org.testng.TestNG.runSuites(TestNG.java:1161)
	at org.testng.TestNG.run(TestNG.java:1129)
	at org.testng.remote.AbstractRemoteTestNG.run(AbstractRemoteTestNG.java:114)
	at org.testng.remote.RemoteTestNG.initAndRun(RemoteTestNG.java:251)
	at org.testng.remote.RemoteTestNG.main(RemoteTestNG.java:77)
]]>
    </failure>
  </testcase> <!-- test1 -->
  <testcase name="test1" time="0.034" classname="runfailedtest1.SampleTest">
    <skipped/>
  </testcase> <!-- test1 -->
  <testcase name="test3" time="0.003" classname="runfailedtest1.SampleTest">
    <failure type="java.lang.AssertionError" message="expected [6] but found [5]">
      <![CDATA[java.lang.AssertionError: expected [6] but found [5]
	at org.testng.Assert.fail(Assert.java:93)
	at org.testng.Assert.failNotEquals(Assert.java:512)
	at org.testng.Assert.assertEqualsImpl(Assert.java:134)
	at org.testng.Assert.assertEquals(Assert.java:115)
	at org.testng.Assert.assertEquals(Assert.java:388)
	at org.testng.Assert.assertEquals(Assert.java:398)
	at runfailedtest1.SampleTest.test3(SampleTest.java:27)
	at sun.reflect.NativeMethodAccessorImpl.invoke0(Native Method)
	at sun.reflect.NativeMethodAccessorImpl.invoke(NativeMethodAccessorImpl.java:62)
	at sun.reflect.DelegatingMethodAccessorImpl.invoke(DelegatingMethodAccessorImpl.java:43)
	at java.lang.reflect.Method.invoke(Method.java:498)
	at org.testng.internal.MethodInvocationHelper.invokeMethod(MethodInvocationHelper.java:108)
	at org.testng.internal.Invoker.invokeMethod(Invoker.java:669)
	at org.testng.internal.Invoker.retryFailed(Invoker.java:1022)
	at org.testng.internal.Invoker.invokeTestMethods(Invoker.java:1223)
	at org.testng.internal.TestMethodWorker.invokeTestMethods(TestMethodWorker.java:125)
	at org.testng.internal.TestMethodWorker.run(TestMethodWorker.java:109)
	at org.testng.TestRunner.privateRun(TestRunner.java:776)
	at org.testng.TestRunner.run(TestRunner.java:634)
	at org.testng.SuiteRunner.runTest(SuiteRunner.java:425)
	at org.testng.SuiteRunner.runSequentially(SuiteRunner.java:420)
	at org.testng.SuiteRunner.privateRun(SuiteRunner.java:385)
	at org.testng.SuiteRunner.run(SuiteRunner.java:334)
	at org.testng.SuiteRunnerWorker.runSuite(SuiteRunnerWorker.java:52)
	at org.testng.SuiteRunnerWorker.run(SuiteRunnerWorker.java:86)
	at org.testng.TestNG.runSuitesSequentially(TestNG.java:1318)
	at org.testng.TestNG.runSuitesLocally(TestNG.java:1243)
	at org.testng.TestNG.runSuites(TestNG.java:1161)
	at org.testng.TestNG.run(TestNG.java:1129)
	at org.testng.remote.AbstractRemoteTestNG.run(AbstractRemoteTestNG.java:114)
	at org.testng.remote.RemoteTestNG.initAndRun(RemoteTestNG.java:251)
	at org.testng.remote.RemoteTestNG.main(RemoteTestNG.java:77)
]]>
    </failure>
  </testcase> <!-- test3 -->
</testsuite> <!-- runfailedtest1.SampleTest -->
